Workbook

Sheet Read me
A1: Topic | B1: Meaning
A2: Purpose | B2: Draft taxonomy maps for PO review. Planning only; implementation HOLD.
A3: Cleanup authority | B3: C1-C10 plus the 13 ADD LEAF paths approved on 3G2026-10-06. Cleaned hierarchy 270 paths; existingT001-T257 IDs preserved; T258-T270 appended. No app/registry/source-sheet edits.
A4: Approved legacy source | B4: PO-approved and reaffirmed Feed Shiekh OLD column:814 unique/899 occurrences. Attached 534-row OLD column is a subset, missing 280; historical Master identity unverified and nonblocking. Evidence on 3C.
A5: No stale targets | B5: Neither the stale 3→4 sheet targets nor the scratch workbook NEW column was used to construct either map.
A6: SUPPORTED DRAFT | B6: A specific source-supported proposal, not PO map approval, runtime configuration or external-contract approval. Legacy source designation is approved separately.
A7: REVIEW | B7: Selected target is blank; remaining evidence/legacy-output review. PO-decided unmapped rows have their own assessment and stay outside product-detail work.
A8: Where to start | B8: PO coverage decisions records all 76 rows:33 mapped,43PO-decided unmapped. Uncertain rows contains 643 other review rows (594 imports+49 website). PO added paths traces 13 approved additions. Complete map tabs own the targets.
A9: Two directions | B9: Import map suggests a full primary path from old values; Website fill map supplies old values from primary choice. The maps are not inverses.
A10: Keep primary detail | B10: Many primary leaves share one website tuple. An unchanged re-import of that tuple must preserve an existing valid primary choice; ambiguous roundtrips are not new conflicts.
A11: Department | B11: Shared department only. No department_key, no new authority key, no outgoing cross-Department target. Missing Beauty/Home & Tech branches remain open.
A12: PO APPROVED | B12: 33 import targets applied from 3G; the 12 previously approved website-fill choices preserved. 12 new website targets are supported drafts; one new website row remains review. No blanket external-contract approval.
... A15: Next checks | B15: No-developer Admin maintenance is required (3A); six remaining design gaps, external consumers, saved configuration, Department coverage and unapproved map outputs remain open.
A16: Cleaned path count | B16: 270
A17: Old unique tuple count | B17: 814
A18: Import proposed / review | B18: 144 supported draft /33 PO approved /594 review /43 PO decided: unmapped pending broad-label policy
A19: Website draft / approved / review | B19: 209 supported draft /12 PO approved /49 review
A20: Input occurrences / dispositions | B20: 899 OLD source occurrences retained;258 base +54 comparator-only =312 cleanup dispositions.
A21: Map version | B21: taxonomy-planning-2026-10-06-v1.4; applies the 3G rulings and 3A no-auto-refill policy. Attachment/source notes incorporated. Replaces v1.3.
A22: Independent verification | B22: PASS — independent AI verified exact approved paths, selected references, unchanged rows, Department preservation, indexes and formulas. Selected website outputs: 221; roundtrip: 86 same, 135 review/unmapped, 0 different; 43 shared legacy targets. Maps are not reversible; preserve primary choices and overrides.
A23: No-developer maintenance | B23: Routine hierarchy, mappings, aliases and legacy-value maintenance must be Admin-managed in-app without development. Governing requirements and remaining six design gaps: https://app.notion.com/p/3f145ee1ec5a81c9a491c2cc4aa89e3c

Sheet Cleaned list
A1: Path ID | B1: Department | C1: Class | D1: Category | E1: Sub-Category | F1: Full four-level path
A2: T001 | B2: Accessories | C2: Bags & Backpacks | D2: Backpacks | E2: Mini Backpacks | F2: Accessories > Bags & Backpacks > Backpacks > Mini Backpacks
A3: T002 | B3: Accessories | C3: Bags & Backpacks | D3: Backpacks | E3: School Backpacks | F3: Accessories > Bags & Backpacks > Backpacks > School Backpacks
A4: T003 | B4: Accessories | C4: Bags & Backpacks | D4: Backpacks | E4: Travel | F4: Accessories > Bags & Backpacks > Backpacks > Travel
A5: T004 | B5: Accessories | C5: Bags & Backpacks | D5: Crossbody & Messenger | E5: Messenger Bags | F5: Accessories > Bags & Backpacks > Crossbody & Messenger > Messenger Bags
A6: T005 | B6: Accessories | C6: Bags & Backpacks | D6: Crossbody Bags | E6: Casual | F6: Accessories > Bags & Backpacks > Crossbody Bags > Casual
A7: T006 | B7: Accessories | C7: Bags & Backpacks | D7: Crossbody Bags | E7: Sport | F7: Accessories > Bags & Backpacks > Crossbody Bags > Sport
A8: T007 | B8: Accessories | C8: Bags & Backpacks | D8: Duffle Bags | E8: Gym Bags | F8: Accessories > Bags & Backpacks > Duffle Bags > Gym Bags
A9: T008 | B9: Accessories | C9: Bags & Backpacks | D9: Duffle Bags | E9: Travel | F9: Accessories > Bags & Backpacks > Duffle Bags > Travel
A10: T009 | B10: Accessories | C10: Bags & Backpacks | D10: Fanny Packs | E10: Shoulder | F10: Accessories > Bags & Backpacks > Fanny Packs > Shoulder
A11: T010 | B11: Accessories | C11: Bags & Backpacks | D11: Fanny Packs | E11: Waist | F11: Accessories > Bags & Backpacks > Fanny Packs > Waist
A12: T011 | B12: Accessories | C12: Bags & Backpacks | D12: Tote Bags | E12: Canvas | F12: Accessories > Bags & Backpacks > Tote Bags > Canvas
... A271: T270 | B271: Footwear | C271: Casual Shoes | D271: Flats | E271: Jelly Flats | F271: Footwear > Casual Shoes > Flats > Jelly Flats

Sheet Import map
A1: Old ID | B1: Incoming old path | C1: Proposed four-level path | D1: Assessment | E1: Reason | F1: Issue | G1: Proposed path ID | H1: Candidate path IDs | I1: Candidate count | J1: Source sheet rows
A2: L001 | B2: > > | D2: REVIEW | E2: Incoming Department is outside the approved shared business Department values; verify source meaning before classification. | F2: DEPARTMENT | I2: 0 | J2: 424
A3: L002 | B3: 0 > 0 > 0 | D3: REVIEW | E3: Incoming Department is outside the approved shared business Department values; verify source meaning before classification. | F3: DEPARTMENT | I3: 0 | J3: 486
A4: L003 | B4: 0 > 0 > Rain Boots | D4: REVIEW | E4: Incoming Department is outside the approved shared business Department values; verify source meaning before classification. | F4: DEPARTMENT | I4: 0 | J4: 897
A5: L004 | B5: 0 > Boots > Combat Boots | D5: REVIEW | E5: Incoming Department is outside the approved shared business Department values; verify source meaning before classification. | F5: DEPARTMENT | I5: 0 | J5: 891
A6: L005 | B6: 0 > Sandal > Thong | D6: REVIEW | E6: Incoming Department is outside the approved shared business Department values; verify source meaning before classification. | F6: DEPARTMENT | I6: 0 | J6: 828
A7: L006 | B7: 0 > Sandals > Flats | D7: REVIEW | E7: Incoming Department is outside the approved shared business Department values; verify source meaning before classification. | F7: DEPARTMENT | I7: 0 | J7: 759
A8: L007 | B8: Accessories > Accessories > Basketball | D8: PO decided: unmapped pending broad-label policy | E8: PO ruling 2026-10-06, LC10: LEAVE UNMAPPED. Retain source evidence and blank target pending broad-label policy; no product-detail Completion Queue task. | F8: BROAD-LABEL POLICY | I8: 0 | J8: 593
A9: L008 | B9: Accessories > Accessories > Face | D9: PO decided: unmapped pending broad-label policy | E9: PO ruling 2026-10-06, LC08: LEAVE UNMAPPED. Retain source evidence and blank target pending broad-label policy; no product-detail Completion Queue task. | F9: BROAD-LABEL POLICY | I9: 0 | J9: 121
A10: L009 | B10: Accessories > Accessories > Jibbitz | C10: Accessories > Gear & Misc > Shoe Care & Accessories > Shoe Charms | D10: PO APPROVED | E10: PO ruling 2026-10-06, LC09: ADD LEAF; select the approved new full path. Planning only; implementation HOLD. | G10: T264 | I10: 0 | J10: 458
A11: L010 | B11: Accessories > Accessories > Shoe Cleaner | C11: Accessories > Gear & Misc > Shoe Care & Accessories > Shoe Cleaner | D11: SUPPORTED DRAFT | E11: Shoe cleaner explicitly named. | G11: T031 | H11: T031 | I11: 1 | J11: 875
A12: L011 | B12: Accessories > Backpacks > Backpack | D12: REVIEW | E12: Material/style/purpose missing. | F12: PRODUCT DETAIL | H12: T001; T002; T003 | I12: 3 | J12: 139
A13: L012 | B13: Accessories > Backpacks > Mini | C13: Accessories > Bags & Backpacks > Backpacks > Mini Backpacks | D13: SUPPORTED DRAFT | E13: Backpack type and mini size explicit. | G13: T001 | H13: T001 | I13: 1 | J13: 677
A14: L013 | B14: Accessories > Bag > Backpack | D14: REVIEW | E14: Material/style/purpose missing. | F14: PRODUCT DETAIL | H14: T001; T002; T003 | I14: 3 | J14: 791
A15: L014 | B15: Accessories > Bags > Backbacks | D15: REVIEW | E15: Material/style/purpose missing. | F15: PRODUCT DETAIL | H15: T001; T002; T003 | I15: 3 | J15: 266
A16: L015 | B16: Accessories > Bags > Backpack | D16: REVIEW | E16: Material/style/purpose missing. | F16: PRODUCT DETAIL | H16: T001; T002; T003 | I16: 3 | J16: 471
A17: L016 | B17: Accessories > Bags > Backpacks | D17: REVIEW | E17: Material/style/purpose missing. | F17: PRODUCT DETAIL | H17: T001; T002; T003 | I17: 3 | J17: 885
A18: L017 | B18: Accessories > Bags > Bags | D18: PO decided: unmapped pending broad-label policy | E18: PO ruling 2026-10-06, LC05: LEAVE UNMAPPED. Retain source evidence and blank target pending broad-label policy; no product-detail Completion Queue task. | F18: BROAD-LABEL POLICY | H18: T001; T002; T003; T004; T005; T006; T007; T008; T009; T010; T011; T012; T013 | I18: 13 | J18: 830
A19: L018 | B19: Accessories > Bags > Clutch | C19: Accessories > Bags & Backpacks > Handbags & Purses > Clutches | D19: PO APPROVED | E19: PO ruling 2026-10-06, LC02: ADD LEAF; select the approved new full path. Planning only; implementation HOLD. | G19: T259 | I19: 0 | J19: 767
A20: L019 | B20: Accessories > Bags > Clutches | C20: Accessories > Bags & Backpacks > Handbags & Purses > Clutches | D20: PO APPROVED | E20: PO ruling 2026-10-06, LC02: ADD LEAF; select the approved new full path. Planning only; implementation HOLD. | G20: T259 | I20: 0 | J20: 108
A21: L020 | B21: Accessories > Bags > Cross Body Bags | D21: REVIEW | E21: Material/style/purpose missing. | F21: PRODUCT DETAIL | H21: T005; T006 | I21: 2 | J21: 141
A22: L021 | B22: Accessories > Bags > Crossbody | D22: REVIEW | E22: Material/style/purpose missing. | F22: PRODUCT DETAIL | H22: T005; T006 | I22: 2 | J22: 619
A23: L022 | B23: Accessories > Bags > Duffle Bag | D23: REVIEW | E23: Material/style/purpose missing. | F23: PRODUCT DETAIL | H23: T007; T008 | I23: 2 | J23: 805
A24: L023 | B24: Accessories > Bags > Duffle Bags | D24: REVIEW | E24: Material/style/purpose missing. | F24: PRODUCT DETAIL | H24: T007; T008 | I24: 2 | J24: 216
A25: L024 | B25: Accessories > Bags > Evening Bag | C25: Accessories > Bags & Backpacks > Handbags & Purses > Evening Bags | D25: PO APPROVED | E25: PO ruling 2026-10-06, LC03: ADD LEAF; select the approved new full path. Planning only; implementation HOLD. | G25: T260 | I25: 0 | J25: 812
A26: L025 | B26: Accessories > Bags > Fanny Pack | D26: REVIEW | E26: Material/style/purpose missing. | F26: PRODUCT DETAIL | H26: T009; T010 | I26: 2 | J26: 131
A27: L026 | B27: Accessories > Bags > Handbags | C27: Accessories > Bags & Backpacks > Handbags & Purses > Handbags | D27: PO APPROVED | E27: PO ruling 2026-10-06, LC01: ADD LEAF; select the approved new full path. Planning only; implementation HOLD. | G27: T258 | I27: 0 | J27: 648
A28: L027 | B28: Accessories > Bags > Handbags and Purses | C28: Accessories > Bags & Backpacks > Handbags & Purses > Handbags | D28: PO APPROVED | E28: PO ruling 2026-10-06, LC01: ADD LEAF; select the approved new full path. Planning only; implementation HOLD. | G28: T258 | I28: 0 | J28: 159
A29: L028 | B29: Accessories > Bags > Messenger Bags | C29: Accessories > Bags & Backpacks > Crossbody & Messenger > Messenger Bags | D29: SUPPORTED DRAFT | E29: Messenger bag type explicit. | G29: T004 | H29: T004 | I29: 1 | J29: 612
A30: L029 | B30: Accessories > Bags > Purses | C30: Accessories > Bags & Backpacks > Handbags & Purses > Handbags | D30: PO APPROVED | E30: PO ruling 2026-10-06, LC01: ADD LEAF; select the approved new full path. Planning only; implementation HOLD. | G30: T258 | I30: 0 | J30: 258
A31: L030 | B31: Accessories > Bags > Shoulder Bags | C31: Accessories > Bags & Backpacks > Handbags & Purses > Shoulder Bags | D31: PO APPROVED | E31: PO ruling 2026-10-06, LC04: ADD LEAF; select the approved new full path. Planning only; implementation HOLD. | G31: T261 | I31: 0 | J31: 742
A32: L031 | B32: Accessories > Bags > Slingback | D32: PO decided: unmapped pending broad-label policy | E32: PO ruling 2026-10-06, LC05: LEAVE UNMAPPED. Retain source evidence and blank target pending broad-label policy; no product-detail Completion Queue task. | F32: BROAD-LABEL POLICY | H32: T001; T002; T003; T004; T005; T006; T007; T008; T009; T010; T011; T012; T013 | I32: 13 | J32: 552
A33: L032 | B33: Accessories > Bags > Tote | D33: REVIEW | E33: Material/style/purpose missing. | F33: PRODUCT DETAIL | H33: T011; T012 | I33: 2 | J33: 270
A34: L033 | B34: Accessories > Bags > Tote Bags | D34: REVIEW | E34: Material/style/purpose missing. | F34: PRODUCT DETAIL | H34: T011; T012 | I34: 2 | J34: 578
A35: L034 | B35: Accessories > Bags & Backpacks > Backpacks | D35: REVIEW | E35: Material/style/purpose missing. | F35: PRODUCT DETAIL | H35: T001; T002; T003 | I35: 3 | J35: 35
A36: L035 | B36: Accessories > Belts > Belt | D36: REVIEW | E36: Belt purpose/material missing. | F36: PRODUCT DETAIL | H36: T024; T025; T026 | I36: 3 | J36: 213
A37: L036 | B37: Accessories > Belts > Belts | D37: REVIEW | E37: Belt purpose/material missing. | F37: PRODUCT DETAIL | H37: T024; T025; T026 | I37: 3 | J37: 822
A38: L037 | B38: Accessories > Belts > None | D38: REVIEW | E38: Missing/placeholder source level; use product evidence and Completion Queue, never a default leaf. | F38: INVALID SOURCE | I38: 0 | J38: 183
A39: L038 | B39: Accessories > Body > Perfumes | C39: Accessories > Beauty & Grooming > Fragrance > Perfume | D39: PO APPROVED | E39: PO ruling 2026-10-06, LC06: ADD LEAF; select the approved new full path. Planning only; implementation HOLD. | G39: T262 | I39: 0 | J39: 276
A40: L039 | B40: Accessories > Bra > Bralette | D40: REVIEW | E40: Accessory Department conflicts with garment/footwear family; no cross-Department auto-map. | F40: DEPARTMENT | I40: 0 | J40: 222
...

Sheet Website fill map
A1: Path ID | B1: Primary four-level path | C1: Proposed legacy path | D1: Assessment | E1: Reason | F1: Relationship | G1: Proposed old ID | H1: Candidate legacy path | I1: Candidate old ID
A2: T001 | B2: Accessories > Bags & Backpacks > Backpacks > Mini Backpacks | C2: Accessories > Backpacks > Mini | D2: SUPPORTED DRAFT | E2: Keeps the named merchandise family; finer ROPI detail remains in the primary fields. | F2: BROADER LEGACY | G2: L012
A3: T002 | B3: Accessories > Bags & Backpacks > Backpacks > School Backpacks | C3: Accessories > Bags > Backpack | D3: SUPPORTED DRAFT | E3: Keeps the named merchandise family; finer ROPI detail remains in the primary fields. | F3: BROADER LEGACY | G3: L015
A4: T003 | B4: Accessories > Bags & Backpacks > Backpacks > Travel | C4: Accessories > Bags > Backpack | D4: SUPPORTED DRAFT | E4: Keeps the named merchandise family; finer ROPI detail remains in the primary fields. | F4: BROADER LEGACY | G4: L015
A5: T004 | B5: Accessories > Bags & Backpacks > Crossbody & Messenger > Messenger Bags | C5: Accessories > Bags > Messenger Bags | D5: SUPPORTED DRAFT | E5: Keeps the named merchandise family; finer ROPI detail remains in the primary fields. | F5: BROADER LEGACY | G5: L028
A6: T005 | B6: Accessories > Bags & Backpacks > Crossbody Bags > Casual | C6: Accessories > Bags > Crossbody | D6: SUPPORTED DRAFT | E6: Keeps the named merchandise family; finer ROPI detail remains in the primary fields. | F6: BROADER LEGACY | G6: L021
A7: T006 | B7: Accessories > Bags & Backpacks > Crossbody Bags > Sport | C7: Accessories > Bags > Crossbody | D7: SUPPORTED DRAFT | E7: Keeps the named merchandise family; finer ROPI detail remains in the primary fields. | F7: BROADER LEGACY | G7: L021
A8: T007 | B8: Accessories > Bags & Backpacks > Duffle Bags > Gym Bags | C8: Accessories > Bags > Duffle Bags | D8: SUPPORTED DRAFT | E8: Keeps the named merchandise family; finer ROPI detail remains in the primary fields. | F8: BROADER LEGACY | G8: L023
A9: T008 | B9: Accessories > Bags & Backpacks > Duffle Bags > Travel | C9: Accessories > Bags > Duffle Bags | D9: SUPPORTED DRAFT | E9: Keeps the named merchandise family; finer ROPI detail remains in the primary fields. | F9: BROADER LEGACY | G9: L023
A10: T009 | B10: Accessories > Bags & Backpacks > Fanny Packs > Shoulder | C10: Accessories > Bags > Fanny Pack | D10: SUPPORTED DRAFT | E10: Keeps the named merchandise family; finer ROPI detail remains in the primary fields. | F10: BROADER LEGACY | G10: L025
A11: T010 | B11: Accessories > Bags & Backpacks > Fanny Packs > Waist | C11: Accessories > Bags > Fanny Pack | D11: SUPPORTED DRAFT | E11: Keeps the named merchandise family; finer ROPI detail remains in the primary fields. | F11: BROADER LEGACY | G11: L025
A12: T011 | B12: Accessories > Bags & Backpacks > Tote Bags > Canvas | C12: Accessories > Bags > Tote Bags | D12: SUPPORTED DRAFT | E12: Keeps the named merchandise family; finer ROPI detail remains in the primary fields. | F12: BROADER LEGACY | G12: L033
A13: T012 | B13: Accessories > Bags & Backpacks > Tote Bags > Leather | C13: Accessories > Bags > Tote Bags | D13: SUPPORTED DRAFT | E13: Keeps the named merchandise family; finer ROPI detail remains in the primary fields. | F13: BROADER LEGACY | G13: L033
A14: T013 | B14: Accessories > Bags & Backpacks > Wallets & Card Holders > Wallets | D14: REVIEW | E14: No defensible same-Department legacy tuple selected from the observed old source; verify missing coverage or required product detail. | F14: REVIEW
A15: T014 | B15: Accessories > Beauty & Grooming > Fragrance > Body Mist | D15: REVIEW | E15: No defensible same-Department legacy tuple selected from the observed old source; verify missing coverage or required product detail. | F15: REVIEW
A16: T015 | B16: Accessories > Beauty & Grooming > Fragrance > Cologne | D16: REVIEW | E16: No defensible same-Department legacy tuple selected from the observed old source; verify missing coverage or required product detail. | F16: REVIEW
A17: T016 | B17: Accessories > Beauty & Grooming > Grooming > Beard Care | D17: REVIEW | E17: No defensible same-Department legacy tuple selected from the observed old source; verify missing coverage or required product detail. | F17: REVIEW
A18: T017 | B18: Accessories > Beauty & Grooming > Grooming > Hair Care | D18: REVIEW | E18: No defensible same-Department legacy tuple selected from the observed old source; verify missing coverage or required product detail. | F18: REVIEW
A19: T018 | B19: Accessories > Beauty & Grooming > Makeup > Eye Color | D19: REVIEW | E19: No defensible same-Department legacy tuple selected from the observed old source; verify missing coverage or required product detail. | F19: REVIEW
A20: T019 | B20: Accessories > Beauty & Grooming > Makeup > Lip Color | D20: REVIEW | E20: No defensible same-Department legacy tuple selected from the observed old source; verify missing coverage or required product detail. | F20: REVIEW
A21: T020 | B21: Accessories > Beauty & Grooming > Skincare > Cleansers | D21: REVIEW | E21: No defensible same-Department legacy tuple selected from the observed old source; verify missing coverage or required product detail. | F21: REVIEW
A22: T021 | B22: Accessories > Beauty & Grooming > Skincare > Moisturizers | D22: REVIEW | E22: No defensible same-Department legacy tuple selected from the observed old source; verify missing coverage or required product detail. | F22: REVIEW
A23: T022 | B23: Accessories > Beauty & Grooming > Sun Care > After Sun | D23: REVIEW | E23: No defensible same-Department legacy tuple selected from the observed old source; verify missing coverage or required product detail. | F23: REVIEW
A24: T023 | B24: Accessories > Beauty & Grooming > Sun Care > Sunscreen | D24: REVIEW | E24: No defensible same-Department legacy tuple selected from the observed old source; verify missing coverage or required product detail. | F24: REVIEW
A25: T024 | B25: Accessories > Belts > Casual > Leather | C25: Accessories > Belts > Belts | D25: SUPPORTED DRAFT | E25: Keeps the named merchandise family; finer ROPI detail remains in the primary fields. | F25: BROADER LEGACY | G25: L036
A26: T025 | B26: Accessories > Belts > Casual > Webbed | C26: Accessories > Belts > Belts | D26: SUPPORTED DRAFT | E26: Keeps the named merchandise family; finer ROPI detail remains in the primary fields. | F26: BROADER LEGACY | G26: L036
A27: T026 | B27: Accessories > Belts > Dress > Leather | C27: Accessories > Belts > Belts | D27: SUPPORTED DRAFT | E27: Keeps the named merchandise family; finer ROPI detail remains in the primary fields. | F27: BROADER LEGACY | G27: L036
A28: T027 | B28: Accessories > Gear & Misc > Personal & Small Accessories > Keychains | D28: REVIEW | E28: No defensible same-Department legacy tuple selected from the observed old source; verify missing coverage or required product detail. | F28: REVIEW
A29: T028 | B29: Accessories > Gear & Misc > Personal & Small Accessories > Sunglasses | C29: Accessories > Sunglasses > Sunglasses | D29: SUPPORTED DRAFT | E29: Keeps the named merchandise family; finer ROPI detail remains in the primary fields. | F29: BROADER LEGACY | G29: L133
A30: T029 | B30: Accessories > Gear & Misc > Personal & Small Accessories > Wallet Chains | D30: REVIEW | E30: No defensible same-Department legacy tuple selected from the observed old source; verify missing coverage or required product detail. | F30: REVIEW
A31: T030 | B31: Accessories > Gear & Misc > Shoe Care & Accessories > Crease Guards | C31: Accessories > Shoe Care > Shoe Care | D31: SUPPORTED DRAFT | E31: Keeps the named merchandise family; finer ROPI detail remains in the primary fields. | F31: BROADER LEGACY | G31: L102
A32: T031 | B32: Accessories > Gear & Misc > Shoe Care & Accessories > Shoe Cleaner | C32: Accessories > Shoe Care > Shoe Cleaner | D32: SUPPORTED DRAFT | E32: Keeps the named merchandise family; finer ROPI detail remains in the primary fields. | F32: BROADER LEGACY | G32: L103
A33: T032 | B33: Accessories > Gear & Misc > Shoe Care & Accessories > Shoe Laces | C33: Accessories > Shoe Care > Shoe Laces | D33: SUPPORTED DRAFT | E33: Keeps the named merchandise family; finer ROPI detail remains in the primary fields. | F33: BROADER LEGACY | G33: L104
A34: T033 | B34: Accessories > Hair Accessories > Clips & Pins > Bobby Pins | D34: REVIEW | E34: No defensible same-Department legacy tuple selected from the observed old source; verify missing coverage or required product detail. | F34: REVIEW
A35: T034 | B35: Accessories > Hair Accessories > Clips & Pins > Hair Clips | D35: REVIEW | E35: No defensible same-Department legacy tuple selected from the observed old source; verify missing coverage or required product detail. | F35: REVIEW
A36: T035 | B36: Accessories > Hair Accessories > Headbands & Ties > Hair Ties | D36: REVIEW | E36: No defensible same-Department legacy tuple selected from the observed old source; verify missing coverage or required product detail. | F36: REVIEW
A37: T036 | B37: Accessories > Hair Accessories > Headbands & Ties > Headbands | D37: REVIEW | E37: No defensible same-Department legacy tuple selected from the observed old source; verify missing coverage or required product detail. | F37: REVIEW
A38: T037 | B38: Accessories > Headwear > Beanies > Balaclava | C38: Accessories > Headwear > Balaclava | D38: SUPPORTED DRAFT | E38: Keeps the named merchandise family; finer ROPI detail remains in the primary fields. | F38: BROADER LEGACY | G38: L088
A39: T038 | B39: Accessories > Headwear > Beanies > Cuffed Beanies | C39: Accessories > Hats > Beanies | D39: SUPPORTED DRAFT | E39: Keeps the named merchandise family; finer ROPI detail remains in the primary fields. | F39: BROADER LEGACY | G39: L069
A40: T039 | B40: Accessories > Headwear > Beanies > Pom | C40: Accessories > Hats > Beanies | D40: SUPPORTED DRAFT | E40: Keeps the named merchandise family; finer ROPI detail remains in the primary fields. | F40: BROADER LEGACY | G40: L069
...

Sheet PO coverage decisions
A1: Decision group | B1: Old ID | C1: Incoming old path | D1: Source sheet rows | E1: Source occurrences | F1: Recorded disposition | G1: Decision page | H1: Selected primary path | I1: Assessment
A2: LC10 | B2: ='Import map'!A8 | C2: ='Import map'!B8 | D2: ='Import map'!J8 | E2: 1 | F2: PO decided: unmapped pending broad-label policy; outside product-detail work | G2: https://app.notion.com/p/3f145ee1ec5a81119a49e55d1c91e77f | H2: ='Import map'!C8 | I2: ='Import map'!D8
A3: LC08 | B3: ='Import map'!A9 | C3: ='Import map'!B9 | D3: ='Import map'!J9 | E3: 1 | F3: PO decided: unmapped pending broad-label policy; outside product-detail work | G3: https://app.notion.com/p/3f145ee1ec5a81119a49e55d1c91e77f | H3: ='Import map'!C9 | I3: ='Import map'!D9
A4: LC09 | B4: ='Import map'!A10 | C4: ='Import map'!B10 | D4: ='Import map'!J10 | E4: 1 | F4: PO approved mapping applied | G4: https://app.notion.com/p/3f145ee1ec5a81119a49e55d1c91e77f | H4: ='Import map'!C10 | I4: ='Import map'!D10
A5: LC05 | B5: ='Import map'!A18 | C5: ='Import map'!B18 | D5: ='Import map'!J18 | E5: 1 | F5: PO decided: unmapped pending broad-label policy; outside product-detail work | G5: https://app.notion.com/p/3f145ee1ec5a81119a49e55d1c91e77f | H5: ='Import map'!C18 | I5: ='Import map'!D18
A6: LC02 | B6: ='Import map'!A19 | C6: ='Import map'!B19 | D6: ='Import map'!J19 | E6: 1 | F6: PO approved mapping applied | G6: https://app.notion.com/p/3f145ee1ec5a81119a49e55d1c91e77f | H6: ='Import map'!C19 | I6: ='Import map'!D19
A7: LC02 | B7: ='Import map'!A20 | C7: ='Import map'!B20 | D7: ='Import map'!J20 | E7: 1 | F7: PO approved mapping applied | G7: https://app.notion.com/p/3f145ee1ec5a81119a49e55d1c91e77f | H7: ='Import map'!C20 | I7: ='Import map'!D20
A8: LC03 | B8: ='Import map'!A25 | C8: ='Import map'!B25 | D8: ='Import map'!J25 | E8: 1 | F8: PO approved mapping applied | G8: https://app.notion.com/p/3f145ee1ec5a81119a49e55d1c91e77f | H8: ='Import map'!C25 | I8: ='Import map'!D25
A9: LC01 | B9: ='Import map'!A27 | C9: ='Import map'!B27 | D9: ='Import map'!J27 | E9: 1 | F9: PO approved mapping applied | G9: https://app.notion.com/p/3f145ee1ec5a81119a49e55d1c91e77f | H9: ='Import map'!C27 | I9: ='Import map'!D27
A10: LC01 | B10: ='Import map'!A28 | C10: ='Import map'!B28 | D10: ='Import map'!J28 | E10: 1 | F10: PO approved mapping applied | G10: https://app.notion.com/p/3f145ee1ec5a81119a49e55d1c91e77f | H10: ='Import map'!C28 | I10: ='Import map'!D28
A11: LC01 | B11: ='Import map'!A30 | C11: ='Import map'!B30 | D11: ='Import map'!J30 | E11: 1 | F11: PO approved mapping applied | G11: https://app.notion.com/p/3f145ee1ec5a81119a49e55d1c91e77f | H11: ='Import map'!C30 | I11: ='Import map'!D30
A12: LC04 | B12: ='Import map'!A31 | C12: ='Import map'!B31 | D12: ='Import map'!J31 | E12: 1 | F12: PO approved mapping applied | G12: https://app.notion.com/p/3f145ee1ec5a81119a49e55d1c91e77f | H12: ='Import map'!C31 | I12: ='Import map'!D31
A13: LC05 | B13: ='Import map'!A32 | C13: ='Import map'!B32 | D13: ='Import map'!J32 | E13: 1 | F13: PO decided: unmapped pending broad-label policy; outside product-detail work | G13: https://app.notion.com/p/3f145ee1ec5a81119a49e55d1c91e77f | H13: ='Import map'!C32 | I13: ='Import map'!D32
A14: LC06 | B14: ='Import map'!A39 | C14: ='Import map'!B39 | D14: ='Import map'!J39 | E14: 1 | F14: PO approved mapping applied | G14: https://app.notion.com/p/3f145ee1ec5a81119a49e55d1c91e77f | H14: ='Import map'!C39 | I14: ='Import map'!D39
A15: LC07 | B15: ='Import map'!A44 | C15: ='Import map'!B44 | D15: ='Import map'!J44 | E15: 1 | F15: PO approved mapping applied | G15: https://app.notion.com/p/3f145ee1ec5a81119a49e55d1c91e77f | H15: ='Import map'!C44 | I15: ='Import map'!D44
A16: LC07 | B16: ='Import map'!A45 | C16: ='Import map'!B45 | D16: ='Import map'!J45 | E16: 1 | F16: PO approved mapping applied | G16: https://app.notion.com/p/3f145ee1ec5a81119a49e55d1c91e77f | H16: ='Import map'!C45 | I16: ='Import map'!D45
A17: LC10 | B17: ='Import map'!A47 | C17: ='Import map'!B47 | D17: ='Import map'!J47 | E17: 1 | F17: PO decided: unmapped pending broad-label policy; outside product-detail work | G17: https://app.notion.com/p/3f145ee1ec5a81119a49e55d1c91e77f | H17: ='Import map'!C47 | I17: ='Import map'!D47
A18: LC11 | B18: ='Import map'!A48 | C18: ='Import map'!B48 | D18: ='Import map'!J48 | E18: 1 | F18: PO approved mapping applied | G18: https://app.notion.com/p/3f145ee1ec5a81119a49e55d1c91e77f | H18: ='Import map'!C48 | I18: ='Import map'!D48
A19: LC01 | B19: ='Import map'!A50 | C19: ='Import map'!B50 | D19: ='Import map'!J50 | E19: 1 | F19: PO approved mapping applied | G19: https://app.notion.com/p/3f145ee1ec5a81119a49e55d1c91e77f | H19: ='Import map'!C50 | I19: ='Import map'!D50
A20: LC02 | B20: ='Import map'!A51 | C20: ='Import map'!B51 | D20: ='Import map'!J51 | E20: 1 | F20: PO approved mapping applied | G20: https://app.notion.com/p/3f145ee1ec5a81119a49e55d1c91e77f | H20: ='Import map'!C51 | I20: ='Import map'!D51
A21: LC02 | B21: ='Import map'!A52 | C21: ='Import map'!B52 | D21: ='Import map'!J52 | E21: 1 | F21: PO approved mapping applied | G21: https://app.notion.com/p/3f145ee1ec5a81119a49e55d1c91e77f | H21: ='Import map'!C52 | I21: ='Import map'!D52
A22: LC01 | B22: ='Import map'!A55 | C22: ='Import map'!B55 | D22: ='Import map'!J55 | E22: 1 | F22: PO approved mapping applied | G22: https://app.notion.com/p/3f145ee1ec5a81119a49e55d1c91e77f | H22: ='Import map'!C55 | I22: ='Import map'!D55
A23: LC01 | B23: ='Import map'!A56 | C23: ='Import map'!B56 | D23: ='Import map'!J56 | E23: 1 | F23: PO approved mapping applied | G23: https://app.notion.com/p/3f145ee1ec5a81119a49e55d1c91e77f | H23: ='Import map'!C56 | I23: ='Import map'!D56
A24: LC01 | B24: ='Import map'!A57 | C24: ='Import map'!B57 | D24: ='Import map'!J57 | E24: 1 | F24: PO approved mapping applied | G24: https://app.notion.com/p/3f145ee1ec5a81119a49e55d1c91e77f | H24: ='Import map'!C57 | I24: ='Import map'!D57
A25: LC04 | B25: ='Import map'!A58 | C25: ='Import map'!B58 | D25: ='Import map'!J58 | E25: 1 | F25: PO approved mapping applied | G25: https://app.notion.com/p/3f145ee1ec5a81119a49e55d1c91e77f | H25: ='Import map'!C58 | I25: ='Import map'!D58
A26: LC12 | B26: ='Import map'!A64 | C26: ='Import map'!B64 | D26: ='Import map'!J64 | E26: 1 | F26: PO approved mapping applied | G26: https://app.notion.com/p/3f145ee1ec5a81119a49e55d1c91e77f | H26: ='Import map'!C64 | I26: ='Import map'!D64
A27: LC13 | B27: ='Import map'!A92 | C27: ='Import map'!B92 | D27: ='Import map'!J92 | E27: 1 | F27: PO decided: unmapped pending broad-label policy; outside product-detail work | G27: https://app.notion.com/p/3f145ee1ec5a81119a49e55d1c91e77f | H27: ='Import map'!C92 | I27: ='Import map'!D92
A28: LC14 | B28: ='Import map'!A95 | C28: ='Import map'!B95 | D28: ='Import map'!J95 | E28: 1 | F28: PO decided: unmapped pending broad-label policy; outside product-detail work | G28: https://app.notion.com/p/3f145ee1ec5a81119a49e55d1c91e77f | H28: ='Import map'!C95 | I28: ='Import map'!D95
A29: LC02 | B29: ='Import map'!A96 | C29: ='Import map'!B96 | D29: ='Import map'!J96 | E29: 1 | F29: PO approved mapping applied | G29: https://app.notion.com/p/3f145ee1ec5a81119a49e55d1c91e77f | H29: ='Import map'!C96 | I29: ='Import map'!D96
A30: LC01 | B30: ='Import map'!A98 | C30: ='Import map'!B98 | D30: ='Import map'!J98 | E30: 1 | F30: PO approved mapping applied | G30: https://app.notion.com/p/3f145ee1ec5a81119a49e55d1c91e77f | H30: ='Import map'!C98 | I30: ='Import map'!D98
A31: LC01 | B31: ='Import map'!A99 | C31: ='Import map'!B99 | D31: ='Import map'!J99 | E31: 1 | F31: PO approved mapping applied | G31: https://app.notion.com/p/3f145ee1ec5a81119a49e55d1c91e77f | H31: ='Import map'!C99 | I31: ='Import map'!D99
A32: LC01 | B32: ='Import map'!A100 | C32: ='Import map'!B100 | D32: ='Import map'!J100 | E32: 1 | F32: PO approved mapping applied | G32: https://app.notion.com/p/3f145ee1ec5a81119a49e55d1c91e77f | H32: ='Import map'!C100 | I32: ='Import map'!D100
A33: LC15 | B33: ='Import map'!A101 | C33: ='Import map'!B101 | D33: ='Import map'!J101 | E33: 1 | F33: PO approved mapping applied | G33: https://app.notion.com/p/3f145ee1ec5a81119a49e55d1c91e77f | H33: ='Import map'!C101 | I33: ='Import map'!D101
A34: LC09 | B34: ='Import map'!A107 | C34: ='Import map'!B107 | D34: ='Import map'!J107 | E34: 1 | F34: PO approved mapping applied | G34: https://app.notion.com/p/3f145ee1ec5a81119a49e55d1c91e77f | H34: ='Import map'!C107 | I34: ='Import map'!D107
A35: LC17 | B35: ='Import map'!A154 | C35: ='Import map'!B154 | D35: ='Import map'!J154 | E35: 1 | F35: PO decided: unmapped pending broad-label policy; outside product-detail work | G35: https://app.notion.com/p/3f145ee1ec5a81119a49e55d1c91e77f | H35: ='Import map'!C154 | I35: ='Import map'!D154
A36: LC17 | B36: ='Import map'!A155 | C36: ='Import map'!B155 | D36: ='Import map'!J155 | E36: 1 | F36: PO decided: unmapped pending broad-label policy; outside product-detail work | G36: https://app.notion.com/p/3f145ee1ec5a81119a49e55d1c91e77f | H36: ='Import map'!C155 | I36: ='Import map'!D155
A37: LC17 | B37: ='Import map'!A244 | C37: ='Import map'!B244 | D37: ='Import map'!J244 | E37: 1 | F37: PO decided: unmapped pending broad-label policy; outside product-detail work | G37: https://app.notion.com/p/3f145ee1ec5a81119a49e55d1c91e77f | H37: ='Import map'!C244 | I37: ='Import map'!D244
A38: LC17 | B38: ='Import map'!A245 | C38: ='Import map'!B245 | D38: ='Import map'!J245 | E38: 1 | F38: PO decided: unmapped pending broad-label policy; outside product-detail work | G38: https://app.notion.com/p/3f145ee1ec5a81119a49e55d1c91e77f | H38: ='Import map'!C245 | I38: ='Import map'!D245
A39: LC17 | B39: ='Import map'!A256 | C39: ='Import map'!B256 | D39: ='Import map'!J256 | E39: 1 | F39: PO decided: unmapped pending broad-label policy; outside product-detail work | G39: https://app.notion.com/p/3f145ee1ec5a81119a49e55d1c91e77f | H39: ='Import map'!C256 | I39: ='Import map'!D256
A40: LC16 | B40: ='Import map'!A355 | C40: ='Import map'!B355 | D40: ='Import map'!J355 | E40: 1 | F40: PO approved mapping applied | G40: https://app.notion.com/p/3f145ee1ec5a81119a49e55d1c91e77f | H40: ='Import map'!C355 | I40: ='Import map'!D355
...

Sheet Uncertain rows
A1: Direction | B1: Reference ID | C1: Source or primary path | D1: Uncertainty | E1: Next action
A2: Source / Department review | B2: ='Import map'!A2 | C2: ='Import map'!B2 | D2: ='Import map'!E2 | E2: Lisa: verify source/Department; PO only for business policy
A3: Source / Department review | B3: ='Import map'!A3 | C3: ='Import map'!B3 | D3: ='Import map'!E3 | E3: Lisa: verify source/Department; PO only for business policy
A4: Source / Department review | B4: ='Import map'!A4 | C4: ='Import map'!B4 | D4: ='Import map'!E4 | E4: Lisa: verify source/Department; PO only for business policy
A5: Source / Department review | B5: ='Import map'!A5 | C5: ='Import map'!B5 | D5: ='Import map'!E5 | E5: Lisa: verify source/Department; PO only for business policy
A6: Source / Department review | B6: ='Import map'!A6 | C6: ='Import map'!B6 | D6: ='Import map'!E6 | E6: Lisa: verify source/Department; PO only for business policy
A7: Source / Department review | B7: ='Import map'!A7 | C7: ='Import map'!B7 | D7: ='Import map'!E7 | E7: Lisa: verify source/Department; PO only for business policy
A8: Product detail | B8: ='Import map'!A12 | C8: ='Import map'!B12 | D8: ='Import map'!E12 | E8: Product Ops: inspect product detail
A9: Product detail | B9: ='Import map'!A14 | C9: ='Import map'!B14 | D9: ='Import map'!E14 | E9: Product Ops: inspect product detail
A10: Product detail | B10: ='Import map'!A15 | C10: ='Import map'!B15 | D10: ='Import map'!E15 | E10: Product Ops: inspect product detail
A11: Product detail | B11: ='Import map'!A16 | C11: ='Import map'!B16 | D11: ='Import map'!E16 | E11: Product Ops: inspect product detail
A12: Product detail | B12: ='Import map'!A17 | C12: ='Import map'!B17 | D12: ='Import map'!E17 | E12: Product Ops: inspect product detail
A13: Product detail | B13: ='Import map'!A21 | C13: ='Import map'!B21 | D13: ='Import map'!E21 | E13: Product Ops: inspect product detail
A14: Product detail | B14: ='Import map'!A22 | C14: ='Import map'!B22 | D14: ='Import map'!E22 | E14: Product Ops: inspect product detail
A15: Product detail | B15: ='Import map'!A23 | C15: ='Import map'!B23 | D15: ='Import map'!E23 | E15: Product Ops: inspect product detail
A16: Product detail | B16: ='Import map'!A24 | C16: ='Import map'!B24 | D16: ='Import map'!E24 | E16: Product Ops: inspect product detail
A17: Product detail | B17: ='Import map'!A26 | C17: ='Import map'!B26 | D17: ='Import map'!E26 | E17: Product Ops: inspect product detail
A18: Product detail | B18: ='Import map'!A33 | C18: ='Import map'!B33 | D18: ='Import map'!E33 | E18: Product Ops: inspect product detail
A19: Product detail | B19: ='Import map'!A34 | C19: ='Import map'!B34 | D19: ='Import map'!E34 | E19: Product Ops: inspect product detail
A20: Product detail | B20: ='Import map'!A35 | C20: ='Import map'!B35 | D20: ='Import map'!E35 | E20: Product Ops: inspect product detail
A21: Product detail | B21: ='Import map'!A36 | C21: ='Import map'!B36 | D21: ='Import map'!E36 | E21: Product Ops: inspect product detail
A22: Product detail | B22: ='Import map'!A37 | C22: ='Import map'!B37 | D22: ='Import map'!E37 | E22: Product Ops: inspect product detail
A23: Source / Department review | B23: ='Import map'!A38 | C23: ='Import map'!B38 | D23: ='Import map'!E38 | E23: Lisa: verify source/Department; PO only for business policy
A24: Source / Department review | B24: ='Import map'!A40 | C24: ='Import map'!B40 | D24: ='Import map'!E40 | E24: Lisa: verify source/Department; PO only for business policy
A25: Source / Department review | B25: ='Import map'!A41 | C25: ='Import map'!B41 | D25: ='Import map'!E41 | E25: Lisa: verify source/Department; PO only for business policy
A26: Source / Department review | B26: ='Import map'!A42 | C26: ='Import map'!B42 | D26: ='Import map'!E42 | E26: Lisa: verify source/Department; PO only for business policy
A27: Source / Department review | B27: ='Import map'!A46 | C27: ='Import map'!B46 | D27: ='Import map'!E46 | E27: Lisa: verify source/Department; PO only for business policy
A28: Source / Department review | B28: ='Import map'!A49 | C28: ='Import map'!B49 | D28: ='Import map'!E49 | E28: Lisa: verify source/Department; PO only for business policy
A29: Product detail | B29: ='Import map'!A53 | C29: ='Import map'!B53 | D29: ='Import map'!E53 | E29: Product Ops: inspect product detail
A30: Product detail | B30: ='Import map'!A54 | C30: ='Import map'!B54 | D30: ='Import map'!E54 | E30: Product Ops: inspect product detail
A31: Product detail | B31: ='Import map'!A59 | C31: ='Import map'!B59 | D31: ='Import map'!E59 | E31: Product Ops: inspect product detail
A32: Product detail | B32: ='Import map'!A60 | C32: ='Import map'!B60 | D32: ='Import map'!E60 | E32: Product Ops: inspect product detail
A33: Source / Department review | B33: ='Import map'!A63 | C33: ='Import map'!B63 | D33: ='Import map'!E63 | E33: Lisa: verify source/Department; PO only for business policy
A34: Source / Department review | B34: ='Import map'!A65 | C34: ='Import map'!B65 | D34: ='Import map'!E65 | E34: Lisa: verify source/Department; PO only for business policy
A35: Product detail | B35: ='Import map'!A66 | C35: ='Import map'!B66 | D35: ='Import map'!E66 | E35: Product Ops: inspect product detail
A36: Product detail | B36: ='Import map'!A67 | C36: ='Import map'!B67 | D36: ='Import map'!E67 | E36: Product Ops: inspect product detail
A37: Product detail | B37: ='Import map'!A68 | C37: ='Import map'!B68 | D37: ='Import map'!E68 | E37: Product Ops: inspect product detail
A38: Product detail | B38: ='Import map'!A69 | C38: ='Import map'!B69 | D38: ='Import map'!E69 | E38: Product Ops: inspect product detail
A39: Product detail | B39: ='Import map'!A70 | C39: ='Import map'!B70 | D39: ='Import map'!E70 | E39: Product Ops: inspect product detail
A40: Product detail | B40: ='Import map'!A71 | C40: ='Import map'!B71 | D40: ='Import map'!E71 | E40: Product Ops: inspect product detail
...

Sheet Old source
A1: Old ID | B1: Raw old combined value | C1: Department | D1: Legacy Class | E1: Legacy Category | F1: Source row numbers | G1: Occurrence count
A2: L001 | B2: > > | F2: 424 | G2: 1
A3: L002 | B3: 0 > 0 > 0 | C3: 0 | D3: 0 | E3: 0 | F3: 486 | G3: 1
A4: L003 | B4: 0 > 0 > Rain Boots | C4: 0 | D4: 0 | E4: Rain Boots | F4: 897 | G4: 1
A5: L004 | B5: 0 > Boots > Combat Boots | C5: 0 | D5: Boots | E5: Combat Boots | F5: 891 | G5: 1
A6: L005 | B6: 0 > Sandal > Thong | C6: 0 | D6: Sandal | E6: Thong | F6: 828 | G6: 1
A7: L006 | B7: 0 > Sandals > Flats | C7: 0 | D7: Sandals | E7: Flats | F7: 759 | G7: 1
A8: L007 | B8: Accessories > Accessories > Basketball | C8: Accessories | D8: Accessories | E8: Basketball | F8: 593 | G8: 1
A9: L008 | B9: Accessories > Accessories > Face | C9: Accessories | D9: Accessories | E9: Face | F9: 121 | G9: 1
A10: L009 | B10: Accessories > Accessories > Jibbitz | C10: Accessories | D10: Accessories | E10: Jibbitz | F10: 458 | G10: 1
A11: L010 | B11: Accessories > Accessories > Shoe Cleaner | C11: Accessories | D11: Accessories | E11: Shoe Cleaner | F11: 875 | G11: 1
A12: L011 | B12: Accessories > Backpacks > Backpack | C12: Accessories | D12: Backpacks | E12: Backpack | F12: 139 | G12: 1
A13: L012 | B13: Accessories > Backpacks > Mini | C13: Accessories | D13: Backpacks | E13: Mini | F13: 677 | G13: 1
A14: L013 | B14: Accessories > Bag > Backpack | C14: Accessories | D14: Bag | E14: Backpack | F14: 791 | G14: 1
... A461: L460 | B461: Clothing > Vests > Winter Vests | C461: Clothing | D461: Vests | E461: Winter Vests | F461: 558 | G461: 1
A462: L461 | B462: Footwear > > | C462: Footwear | F462: 381 | G462: 1
A463: L462 | B463: Footwear > 0 > 0 | C463: Footwear | D463: 0 | E463: 0 | F463: 562 | G463: 1
A464: L463 | B464: Footwear > Athletic > Basketball | C464: Footwear | D464: Athletic | E464: Basketball | F464: 123 | G464: 1
A465: L464 | B465: Footwear > Athletic > Basketball Shoe | C465: Footwear | D465: Athletic | E465: Basketball Shoe | F465: 501 | G465: 1
A466: L465 | B466: Footwear > Athletic > FALSE | C466: Footwear | D466: Athletic | E466: FALSE | F466: 248, 361 | G466: 2
A467: L466 | B467: Footwear > Athletic > Lifestyle | C467: Footwear | D467: Athletic | E467: Lifestyle | F467: 206, 360 | G467: 2
A468: L467 | B468: Footwear > Athletic > Running | C468: Footwear | D468: Athletic | E468: Running | F468: 185 | G468: 1
A469: L468 | B469: Footwear > Athletic > Soccer | C469: Footwear | D469: Athletic | E469: Soccer | F469: 543 | G469: 1
A470: L469 | B470: Footwear > Boat Shoes > Boat | C470: Footwear | D470: Boat Shoes | E470: Boat | F470: 733 | G470: 1
A471: L470 | B471: Footwear > Boat Shoes > Boat Shoes | C471: Footwear | D471: Boat Shoes | E471: Boat Shoes | F471: 268, 362 | G471: 2
A472: L471 | B472: Footwear > Boots > | C472: Footwear | D472: Boots | F472: 824 | G472: 1
A473: L472 | B473: Footwear > Boots > 0 | C473: Footwear | D473: Boots | E473: 0 | F473: 91, 284 | G473: 2
A474: L473 | B474: Footwear > Boots > 6 Inch Premium | C474: Footwear | D474: Boots | E474: 6 Inch Premium | F474: 68, 286 | G474: 2
A475: L474 | B475: Footwear > Boots > 6-Inch Boot | C475: Footwear | D475: Boots | E475: 6-Inch Boot | F475: 192, 285 | G475: 2
A476: L475 | B476: Footwear > Boots > Ankle Boots | C476: Footwear | D476: Boots | E476: Ankle Boots | F476: 45, 287 | G476: 2
A477: L476 | B477: Footwear > Boots > Athletic | C477: Footwear | D477: Boots | E477: Athletic | F477: 745 | G477: 1
A478: L477 | B478: Footwear > Boots > Basketball Shoe | C478: Footwear | D478: Boots | E478: Basketball Shoe | F478: 818 | G478: 1
A479: L478 | B479: Footwear > Boots > Block Heel | C479: Footwear | D479: Boots | E479: Block Heel | F479: 730 | G479: 1
A480: L479 | B480: Footwear > Boots > Booties | C480: Footwear | D480: Boots | E480: Booties | F480: 77, 288 | G480: 2
A481: L480 | B481: Footwear > Boots > Boots | C481: Footwear | D481: Boots | E481: Boots | F481: 149, 289 | G481: 2
A482: L481 | B482: Footwear > Boots > Chelsea | C482: Footwear | D482: Boots | E482: Chelsea | F482: 551 | G482: 1
A483: L482 | B483: Footwear > Boots > Chukka | C483: Footwear | D483: Boots | E483: Chukka | F483: 157, 290 | G483: 2
A484: L483 | B484: Footwear > Boots > Chunky | C484: Footwear | D484: Boots | E484: Chunky | F484: 409 | G484: 1
... A815: L814 | B815: WOMEN > Clothing > Tank Top | C815: WOMEN | D815: Clothing | E815: Tank Top | F815: 24 | G815: 1

Sheet Cleanup trace
A1: Source | B1: Source row | C1: Original full path | D1: Cleanup rule | E1: Disposition | F1: Retained target IDs | G1: Retained target paths | H1: Interpretation
A2: May19 | B2: 2 | C2: Accessories > Bags & Backpacks > Backpacks > Mini Backpacks | D2: BASE | E2: KEEP | F2: T001 | G2: Accessories > Bags & Backpacks > Backpacks > Mini Backpacks | H2: Approval covers list structure; removed broad paths do not automatically choose a narrower leaf.
A3: May19 | B3: 3 | C3: Accessories > Bags & Backpacks > Backpacks > School Backpacks | D3: BASE | E3: KEEP | F3: T002 | G3: Accessories > Bags & Backpacks > Backpacks > School Backpacks | H3: Approval covers list structure; removed broad paths do not automatically choose a narrower leaf.
A4: May19 | B4: 4 | C4: Accessories > Bags & Backpacks > Backpacks > Travel | D4: BASE | E4: KEEP | F4: T003 | G4: Accessories > Bags & Backpacks > Backpacks > Travel | H4: Approval covers list structure; removed broad paths do not automatically choose a narrower leaf.
A5: May19 | B5: 5 | C5: Accessories > Bags & Backpacks > Crossbody & Messenger > Fanny Packs/Waist Bags | D5: C7 | E5: REMOVE BROAD ROUTE | F5: T009; T010 | G5: Accessories > Bags & Backpacks > Fanny Packs > Shoulder; Accessories > Bags & Backpacks > Fanny Packs > Waist | H5: Approval covers list structure; removed broad paths do not automatically choose a narrower leaf.
A6: May19 | B6: 6 | C6: Accessories > Bags & Backpacks > Crossbody & Messenger > Messenger Bags | D6: BASE | E6: KEEP | F6: T004 | G6: Accessories > Bags & Backpacks > Crossbody & Messenger > Messenger Bags | H6: Approval covers list structure; removed broad paths do not automatically choose a narrower leaf.
A7: May19 | B7: 7 | C7: Accessories > Bags & Backpacks > Crossbody Bags > Casual | D7: BASE | E7: KEEP | F7: T005 | G7: Accessories > Bags & Backpacks > Crossbody Bags > Casual | H7: Approval covers list structure; removed broad paths do not automatically choose a narrower leaf.
A8: May19 | B8: 8 | C8: Accessories > Bags & Backpacks > Crossbody Bags > Sport | D8: BASE | E8: KEEP | F8: T006 | G8: Accessories > Bags & Backpacks > Crossbody Bags > Sport | H8: Approval covers list structure; removed broad paths do not automatically choose a narrower leaf.
A9: May19 | B9: 9 | C9: Accessories > Bags & Backpacks > Duffle Bags > Gym Bags | D9: BASE | E9: KEEP | F9: T007 | G9: Accessories > Bags & Backpacks > Duffle Bags > Gym Bags | H9: Approval covers list structure; removed broad paths do not automatically choose a narrower leaf.
A10: May19 | B10: 10 | C10: Accessories > Bags & Backpacks > Duffle Bags > Travel | D10: BASE | E10: KEEP | F10: T008 | G10: Accessories > Bags & Backpacks > Duffle Bags > Travel | H10: Approval covers list structure; removed broad paths do not automatically choose a narrower leaf.
A11: May19 | B11: 11 | C11: Accessories > Bags & Backpacks > Fanny Packs > Shoulder | D11: BASE | E11: KEEP | F11: T009 | G11: Accessories > Bags & Backpacks > Fanny Packs > Shoulder | H11: Approval covers list structure; removed broad paths do not automatically choose a narrower leaf.
A12: May19 | B12: 12 | C12: Accessories > Bags & Backpacks > Fanny Packs > Waist | D12: BASE | E12: KEEP | F12: T010 | G12: Accessories > Bags & Backpacks > Fanny Packs > Waist | H12: Approval covers list structure; removed broad paths do not automatically choose a narrower leaf.
A13: May19 | B13: 13 | C13: Accessories > Bags & Backpacks > Handbags & Totes > Totes | D13: C7 | E13: REMOVE BROAD ROUTE | F13: T011; T012 | G13: Accessories > Bags & Backpacks > Tote Bags > Canvas; Accessories > Bags & Backpacks > Tote Bags > Leather | H13: Approval covers list structure; removed broad paths do not automatically choose a narrower leaf.
... A259: May19 | B259: 259 | C259: Footwear > Sneakers > Training > Weightlifting | D259: BASE | E259: KEEP | F259: T257 | G259: Footwear > Sneakers > Training > Weightlifting | H259: Approval covers list structure; removed broad paths do not automatically choose a narrower leaf.
A260: Comparator | B260: 22 | C260: Accessories > Gear & Misc > Shoe Care > Shoe Cleaner | D260: C4 | E260: OMIT COMPETING OR BROAD ROUTE | H260: See approved cleanup C4; no automatic import alias is implied.
A261: Comparator | B261: 23 | C261: Accessories > Gear & Misc > Shoe Care > Shoe Laces | D261: C4 | E261: OMIT COMPETING OR BROAD ROUTE | H261: See approved cleanup C4; no automatic import alias is implied.
A262: Comparator | B262: 40 | C262: Clothing > Team Gear & Licensed > Fanwear Hats > MLB | D262: C5 | E262: OMIT COMPETING OR BROAD ROUTE | H262: See approved cleanup C5; no automatic import alias is implied.
A263: Comparator | B263: 41 | C263: Clothing > Team Gear & Licensed > Fanwear Hats > NBA | D263: C5 | E263: OMIT COMPETING OR BROAD ROUTE | H263: See approved cleanup C5; no automatic import alias is implied.
A264: Comparator | B264: 42 | C264: Clothing > Team Gear & Licensed > Fanwear Hats > NFL | D264: C5 | E264: OMIT COMPETING OR BROAD ROUTE | H264: See approved cleanup C5; no automatic import alias is implied.
A265: Comparator | B265: 54 | C265: Clothing > Activewear > Outerwear & Jackets > Jackets | D265: C2 | E265: OMIT COMPETING OR BROAD ROUTE | H265: See approved cleanup C2; no automatic import alias is implied.
A266: Comparator | B266: 55 | C266: Clothing > Activewear > Tops > Performance Tees | D266: C2 | E266: OMIT COMPETING OR BROAD ROUTE | H266: See approved cleanup C2; no automatic import alias is implied.
A267: Comparator | B267: 56 | C267: Clothing > Activewear > Tops > Tank Tops | D267: C2 | E267: OMIT COMPETING OR BROAD ROUTE | H267: See approved cleanup C2; no automatic import alias is implied.
A268: Comparator | B268: 68 | C268: Clothing > Bottoms > Pants > Sweatpants | D268: C8 | E268: OMIT COMPETING OR BROAD ROUTE | H268: See approved cleanup C8; no automatic import alias is implied.
A269: Comparator | B269: 87 | C269: Clothing > Intimates & Sleepwear > Bras > Sports Bras | D269: C2 | E269: MERGED WITH APPROVED HOME | F269: T103 | G269: Clothing > Intimates & Sleepwear > Bras > Sports Bras | H269: See approved cleanup C2; no automatic import alias is implied.
A270: Comparator | B270: 94 | C270: Clothing > Intimates & Sleepwear > Underwear > Underwear | D270: C3 | E270: OMIT COMPETING OR BROAD ROUTE | H270: See approved cleanup C3; no automatic import alias is implied.
A271: Comparator | B271: 107 | C271: Clothing > Outerwear & Jackets > Jackets > Leather Jackets | D271: C8 | E271: OMIT COMPETING OR BROAD ROUTE | H271: See approved cleanup C8; no automatic import alias is implied.
A272: Comparator | B272: 111 | C272: Clothing > Swimwear > Boardshorts > Boardshorts | D272: C3 | E272: OMIT COMPETING OR BROAD ROUTE | H272: See approved cleanup C3; no automatic import alias is implied.
A273: Comparator | B273: 112 | C273: Clothing > Swimwear > Briefs > Briefs | D273: C3 | E273: OMIT COMPETING OR BROAD ROUTE | H273: See approved cleanup C3; no automatic import alias is implied.
A274: Comparator | B274: 113 | C274: Clothing > Swimwear > Trunks > Trunks | D274: C3 | E274: OMIT COMPETING OR BROAD ROUTE | H274: See approved cleanup C3; no automatic import alias is implied.
A275: Comparator | B275: 114 | C275: Clothing > Swimwear > Bikinis > Bikinis | D275: C3 | E275: OMIT COMPETING OR BROAD ROUTE | H275: See approved cleanup C3; no automatic import alias is implied.
A276: Comparator | B276: 115 | C276: Clothing > Swimwear > Cover-Ups > Cover-Ups | D276: C3 | E276: OMIT COMPETING OR BROAD ROUTE | H276: See approved cleanup C3; no automatic import alias is implied.
A277: Comparator | B277: 116 | C277: Clothing > Swimwear > One-Piece > One-Piece | D277: C3 | E277: OMIT COMPETING OR BROAD ROUTE | H277: See approved cleanup C3; no automatic import alias is implied.
A278: Comparator | B278: 120 | C278: Clothing > Tops > Hoodies & Sweatshirts > Crewneck Sweatshirts | D278: C1 | E278: OMIT COMPETING OR BROAD ROUTE | H278: See approved cleanup C1; no automatic import alias is implied.
A279: Comparator | B279: 121 | C279: Clothing > Tops > Hoodies & Sweatshirts > Pullover Hoodies | D279: C1 | E279: OMIT COMPETING OR BROAD ROUTE | H279: See approved cleanup C1; no automatic import alias is implied.
A280: Comparator | B280: 122 | C280: Clothing > Tops > Hoodies & Sweatshirts > Zip-Up Hoodies | D280: C1 | E280: OMIT COMPETING OR BROAD ROUTE | H280: See approved cleanup C1; no automatic import alias is implied.
A281: Comparator | B281: 129 | C281: Clothing > Tops > Shirts & Blouses > Long Sleeve Wovens | D281: C9 | E281: ADD REAL DETAIL | F281: T153 | G281: Clothing > Tops > Shirts & Blouses > Long Sleeve Wovens | H281: See approved cleanup C9; no automatic import alias is implied.
A282: Comparator | B282: 130 | C282: Clothing > Tops > Shirts & Blouses > Short Sleeve Wovens | D282: C9 | E282: ADD REAL DETAIL | F282: T155 | G282: Clothing > Tops > Shirts & Blouses > Short Sleeve Wovens | H282: See approved cleanup C9; no automatic import alias is implied.
A283: Comparator | B283: 133 | C283: Clothing > Tops > Sweaters & Knits > Polos | D283: C1 | E283: OMIT COMPETING OR BROAD ROUTE | H283: See approved cleanup C1; no automatic import alias is implied.
A284: Comparator | B284: 134 | C284: Clothing > Tops > Sweaters & Polos > Rugby Shirts | D284: C1 | E284: OMIT COMPETING OR BROAD ROUTE | H284: See approved cleanup C1; no automatic import alias is implied.
A285: Comparator | B285: 135 | C285: Clothing > Tops > Sweaters > Cardigans | D285: C1 | E285: OMIT COMPETING OR BROAD ROUTE | H285: See approved cleanup C1; no automatic import alias is implied.
...

Sheet Sources
A1: Source | B1: URL | C1: Tab / read | D1: Use / limitation | E1: SHA256 / method noted in Tab-read
A2: May 19 | B2: https://docs.google.com/spreadsheets/d/1WayzEn2EqB-2VZCH_vP8sKALEglqf16S1I94_WFpE5o/edit | C2: Sheet 1 A1:F270 | D2: 258 original base paths; source unchanged | E2: ef009be97f5d3bfd31d6e56863e73ac4d4ef9e70d52f1daea632418e25ac9e1d
A3: Comparator | B3: https://docs.google.com/spreadsheets/d/1oiGns5i3hUj9j2_vEG5Ouw4EmgtixrzM5SDjQKp2LvY/edit | C3: Production Taxonomy A1:F250 | D3: 241 paths; only 54 non-base paths require separate disposition | E3: ed959e168d4a7b87a943c23004eeeacfd55294be8d72563cf759e2a44eaa1bcd
A4: Approved old 814 source | B4: https://docs.google.com/spreadsheets/d/1TAT6Lk2Qp2pfnB9rBLZmh-6kZSB-l3SJ-MQSbi3tVL0/edit#gid=999937790 | C4: Old -> New Mapping A1:A1365 | D4: PO designated 2026-10-06;899 occurrences/814 unique. OLD column only. Live values still equal approved capture. Master comparison blocked by missing tab in supplied file; source designation stays approved. | E4: 95acae7059b89986cd92e4ef9b67545aff927e5ab678a22a5e5ec2c1b716d0cd
A5: Approved cleanup | B5: https://app.notion.com/p/3f145ee1ec5a81c8bd2de7db0bb527c2 | C5: C1-C10 | D5: Approved structure directions; no product map approval
A6: Design | B6: https://app.notion.com/p/3f145ee1ec5a81c9a491c2cc4aa89e3c | C6: Shared Department and R14 contract | D6: Planning proposal; implementation HOLD
A7: Master identity — unverified | B7: https://docs.google.com/spreadsheets/d/1MYFO2vyKSYkHnzCBQDRxaK08nDEM5TUXr83lSYHCIV0/edit | C7: Metadata read 2026-10-06; title Product Attributes for Ropi | D7: Supplied MasterID has no Old→New Mapping tab. Historical identity remains unverified but does not block planning with the approved 814 source. See 3C.
A8: Approved OLD — column-value hash | B8: https://docs.google.com/spreadsheets/d/1TAT6Lk2Qp2pfnB9rBLZmh-6kZSB-l3SJ-MQSbi3tVL0/edit#gid=999937790 | C8: Old -> New Mapping A1:A1365; SHA-256 of UTF-8 compact JSON data-value array | D8: Exclude header/trailing blank cells; preserve order, duplicates, case, spelling and whitespace.899 data values/814 exact unique strings; equal approved capture. Other source hashes above are captured-response file hashes. | E8: 7c3d3c488387ff7df2db1be0a6ef337e7de38a2239c1a25b130d41578c2989fb
A9: Identity-check evidence | B9: https://app.notion.com/p/3f145ee1ec5a81aabd64c52ae357b4e9 | C9: 3C — Taxonomy inventory and source checks | D9: 3C owns missing-tab finding and 534-row attachment subset/280 missing comparison. Source designation remains approved.
A10: PO coverage decisions | B10: https://app.notion.com/p/3f145ee1ec5a81119a49e55d1c91e77f | C10: 3G — all 26 groups decided 2026-10-06 | D10: 13 new paths;33 import targets set;43 decided unmapped. LC16→T103; LC26→T219. Implementation HOLD.
A11: PO maintenance and refill ruling | B11: https://app.notion.com/p/3f145ee1ec5a81c9a491c2cc4aa89e3c | C11: No-developer maintenance requirement | D11: No automatic existing-product refill; Admin self-service required; remaining design work is tracked on 3A.
A12: Attached older map comparison | B12: https://app.notion.com/p/3f145ee1ec5a81aabd64c52ae357b4e9 | C12: Snapshot 3 -> 4 taxonomy level OLD A2:A535; compact UTF-8 JSON data-value hash | D12: 534 unique/occurrences; all in 814;280 approved tuples absent;0 attachment-only; targets excluded. Snapshot comparison, not fresh live-sheet read. | E12: 494c67e6f1cff1608b7ef149b682f553a2ca5d29784f966839ac80a1fe4ccacb

Sheet PO added paths
A1: New path ID | B1: PO group | C1: Approved full path | D1: Authority | E1: Website old ID | F1: Website assessment
A2: T258 | B2: LC01 | C2: ='Cleaned list'!F259 | D2: https://app.notion.com/p/3f145ee1ec5a81119a49e55d1c91e77f | E2: ='Website fill map'!G259 | F2: ='Website fill map'!D259
A3: T259 | B3: LC02 | C3: ='Cleaned list'!F260 | D3: https://app.notion.com/p/3f145ee1ec5a81119a49e55d1c91e77f | E3: ='Website fill map'!G260 | F3: ='Website fill map'!D260
A4: T260 | B4: LC03 | C4: ='Cleaned list'!F261 | D4: https://app.notion.com/p/3f145ee1ec5a81119a49e55d1c91e77f | E4: ='Website fill map'!G261 | F4: ='Website fill map'!D261
A5: T261 | B5: LC04 | C5: ='Cleaned list'!F262 | D5: https://app.notion.com/p/3f145ee1ec5a81119a49e55d1c91e77f | E5: ='Website fill map'!G262 | F5: ='Website fill map'!D262
A6: T262 | B6: LC06 | C6: ='Cleaned list'!F263 | D6: https://app.notion.com/p/3f145ee1ec5a81119a49e55d1c91e77f | E6: ='Website fill map'!G263 | F6: ='Website fill map'!D263
A7: T263 | B7: LC07 | C7: ='Cleaned list'!F264 | D7: https://app.notion.com/p/3f145ee1ec5a81119a49e55d1c91e77f | E7: ='Website fill map'!G264 | F7: ='Website fill map'!D264
A8: T264 | B8: LC09 | C8: ='Cleaned list'!F265 | D8: https://app.notion.com/p/3f145ee1ec5a81119a49e55d1c91e77f | E8: ='Website fill map'!G265 | F8: ='Website fill map'!D265
A9: T265 | B9: LC11 | C9: ='Cleaned list'!F266 | D9: https://app.notion.com/p/3f145ee1ec5a81119a49e55d1c91e77f | E9: ='Website fill map'!G266 | F9: ='Website fill map'!D266
A10: T266 | B10: LC12 | C10: ='Cleaned list'!F267 | D10: https://app.notion.com/p/3f145ee1ec5a81119a49e55d1c91e77f | E10: ='Website fill map'!G267 | F10: ='Website fill map'!D267
